2020-11-05 14:51:50,999 ERROR: Exception on /user/mayank1729 [GET] [in /home/mayank1729/microblog/venv/lib/python3.8/site-packages/flask/app.py:1891]
Traceback (most recent call last):
  File "/home/mayank1729/microblog/venv/lib/python3.8/site-packages/flask/app.py", line 2447, in wsgi_app
    response = self.full_dispatch_request()
  File "/home/mayank1729/microblog/venv/lib/python3.8/site-packages/flask/app.py", line 1952, in full_dispatch_request
    rv = self.handle_user_exception(e)
  File "/home/mayank1729/microblog/venv/lib/python3.8/site-packages/flask/app.py", line 1821, in handle_user_exception
    reraise(exc_type, exc_value, tb)
  File "/home/mayank1729/microblog/venv/lib/python3.8/site-packages/flask/_compat.py", line 39, in reraise
    raise value
  File "/home/mayank1729/microblog/venv/lib/python3.8/site-packages/flask/app.py", line 1950, in full_dispatch_request
    rv = self.dispatch_request()
  File "/home/mayank1729/microblog/venv/lib/python3.8/site-packages/flask/app.py", line 1936, in dispatch_request
    return self.view_functions[rule.endpoint](**req.view_args)
  File "/home/mayank1729/microblog/venv/lib/python3.8/site-packages/flask_login/utils.py", line 272, in decorated_view
    return func(*args, **kwargs)
  File "/home/mayank1729/microblog/app/routes.py", line 85, in user
    return render_template('user.html',user=user, posts=posts,form=form, next_url = next_url, prev_url = prev_url)
  File "/home/mayank1729/microblog/venv/lib/python3.8/site-packages/flask/templating.py", line 137, in render_template
    return _render(
  File "/home/mayank1729/microblog/venv/lib/python3.8/site-packages/flask/templating.py", line 120, in _render
    rv = template.render(context)
  File "/home/mayank1729/microblog/venv/lib/python3.8/site-packages/jinja2/environment.py", line 1090, in render
    self.environment.handle_exception()
  File "/home/mayank1729/microblog/venv/lib/python3.8/site-packages/jinja2/environment.py", line 832, in handle_exception
    reraise(*rewrite_traceback_stack(source=source))
  File "/home/mayank1729/microblog/venv/lib/python3.8/site-packages/jinja2/_compat.py", line 28, in reraise
    raise value.with_traceback(tb)
  File "/home/mayank1729/microblog/app/templates/user.html", line 1, in top-level template code
    {% extends "base.html" %}
  File "/home/mayank1729/microblog/app/templates/base.html", line 31, in top-level template code
    {% block content %}{% endblock %}
  File "/home/mayank1729/microblog/app/templates/user.html", line 32, in block "content"
    {% for post in posts %}
TypeError: 'Pagination' object is not iterable
2020-11-05 14:55:05,156 INFO: Microblog startup [in /home/mayank1729/microblog/app/__init__.py:40]
2020-11-05 20:10:37,379 INFO: Microblog startup [in /home/mayank1729/microblog/app/__init__.py:43]
2020-11-05 20:35:35,235 INFO: Microblog startup [in /home/mayank1729/microblog/app/__init__.py:43]
2020-11-05 21:19:51,407 INFO: Microblog startup [in /home/mayank1729/microblog/app/__init__.py:43]
2020-11-05 21:24:28,483 INFO: Microblog startup [in /home/mayank1729/microblog/app/__init__.py:43]
2020-11-05 21:32:24,035 INFO: Microblog startup [in /home/mayank1729/microblog/app/__init__.py:43]
2020-11-05 21:34:47,662 INFO: Microblog startup [in /home/mayank1729/microblog/app/__init__.py:43]
2020-11-05 21:39:53,979 INFO: Microblog startup [in /home/mayank1729/microblog/app/__init__.py:43]
2020-11-05 21:41:06,069 INFO: Microblog startup [in /home/mayank1729/microblog/app/__init__.py:43]
2020-11-05 21:42:55,628 INFO: Microblog startup [in /home/mayank1729/microblog/app/__init__.py:43]
2020-11-05 21:44:27,403 INFO: Microblog startup [in /home/mayank1729/microblog/app/__init__.py:43]
2020-11-05 21:44:46,962 INFO: Microblog startup [in /home/mayank1729/microblog/app/__init__.py:43]
2020-11-05 21:45:10,853 ERROR: Exception on /reset_password_request [POST] [in /home/mayank1729/microblog/venv/lib/python3.8/site-packages/flask/app.py:1891]
Traceback (most recent call last):
  File "/home/mayank1729/microblog/venv/lib/python3.8/site-packages/flask/app.py", line 2447, in wsgi_app
    response = self.full_dispatch_request()
  File "/home/mayank1729/microblog/venv/lib/python3.8/site-packages/flask/app.py", line 1952, in full_dispatch_request
    rv = self.handle_user_exception(e)
  File "/home/mayank1729/microblog/venv/lib/python3.8/site-packages/flask/app.py", line 1821, in handle_user_exception
    reraise(exc_type, exc_value, tb)
  File "/home/mayank1729/microblog/venv/lib/python3.8/site-packages/flask/_compat.py", line 39, in reraise
    raise value
  File "/home/mayank1729/microblog/venv/lib/python3.8/site-packages/flask/app.py", line 1950, in full_dispatch_request
    rv = self.dispatch_request()
  File "/home/mayank1729/microblog/venv/lib/python3.8/site-packages/flask/app.py", line 1936, in dispatch_request
    return self.view_functions[rule.endpoint](**req.view_args)
  File "/home/mayank1729/microblog/app/routes.py", line 160, in reset_password_request
    send_password_rest_email(user)
NameError: name 'send_password_rest_email' is not defined
2020-11-05 21:46:02,623 INFO: Microblog startup [in /home/mayank1729/microblog/app/__init__.py:43]
2020-11-05 21:46:06,285 ERROR: Exception on /reset_password_request [POST] [in /home/mayank1729/microblog/venv/lib/python3.8/site-packages/flask/app.py:1891]
Traceback (most recent call last):
  File "/home/mayank1729/microblog/venv/lib/python3.8/site-packages/flask/app.py", line 2447, in wsgi_app
    response = self.full_dispatch_request()
  File "/home/mayank1729/microblog/venv/lib/python3.8/site-packages/flask/app.py", line 1952, in full_dispatch_request
    rv = self.handle_user_exception(e)
  File "/home/mayank1729/microblog/venv/lib/python3.8/site-packages/flask/app.py", line 1821, in handle_user_exception
    reraise(exc_type, exc_value, tb)
  File "/home/mayank1729/microblog/venv/lib/python3.8/site-packages/flask/_compat.py", line 39, in reraise
    raise value
  File "/home/mayank1729/microblog/venv/lib/python3.8/site-packages/flask/app.py", line 1950, in full_dispatch_request
    rv = self.dispatch_request()
  File "/home/mayank1729/microblog/venv/lib/python3.8/site-packages/flask/app.py", line 1936, in dispatch_request
    return self.view_functions[rule.endpoint](**req.view_args)
  File "/home/mayank1729/microblog/app/routes.py", line 160, in reset_password_request
    send_password_reset_email(user)
  File "/home/mayank1729/microblog/app/email.py", line 16, in send_password_reset_email
    token = user.get_password_reset_token()
AttributeError: 'User' object has no attribute 'get_password_reset_token'
2020-11-05 21:47:05,287 INFO: Microblog startup [in /home/mayank1729/microblog/app/__init__.py:43]
2020-11-05 21:47:08,626 ERROR: Exception on /reset_password_request [POST] [in /home/mayank1729/microblog/venv/lib/python3.8/site-packages/flask/app.py:1891]
Traceback (most recent call last):
  File "/home/mayank1729/microblog/venv/lib/python3.8/site-packages/flask/app.py", line 2447, in wsgi_app
    response = self.full_dispatch_request()
  File "/home/mayank1729/microblog/venv/lib/python3.8/site-packages/flask/app.py", line 1952, in full_dispatch_request
    rv = self.handle_user_exception(e)
  File "/home/mayank1729/microblog/venv/lib/python3.8/site-packages/flask/app.py", line 1821, in handle_user_exception
    reraise(exc_type, exc_value, tb)
  File "/home/mayank1729/microblog/venv/lib/python3.8/site-packages/flask/_compat.py", line 39, in reraise
    raise value
  File "/home/mayank1729/microblog/venv/lib/python3.8/site-packages/flask/app.py", line 1950, in full_dispatch_request
    rv = self.dispatch_request()
  File "/home/mayank1729/microblog/venv/lib/python3.8/site-packages/flask/app.py", line 1936, in dispatch_request
    return self.view_functions[rule.endpoint](**req.view_args)
  File "/home/mayank1729/microblog/app/routes.py", line 160, in reset_password_request
    send_password_reset_email(user)
  File "/home/mayank1729/microblog/app/email.py", line 17, in send_password_reset_email
    send_email('[Microblog] Reset Your Password',sender = app.config['ADMINS'][0],recipients=[user.email],text_body = render_template('email/reset_password.txt',user=user, token=token),html_body=render_template('email/reset_password.html',user=user, token=token))
NameError: name 'send_email' is not defined
2020-11-05 21:50:22,849 INFO: Microblog startup [in /home/mayank1729/microblog/app/__init__.py:43]
2020-11-05 21:50:25,921 ERROR: Exception on /reset_password_request [POST] [in /home/mayank1729/microblog/venv/lib/python3.8/site-packages/flask/app.py:1891]
Traceback (most recent call last):
  File "/home/mayank1729/microblog/venv/lib/python3.8/site-packages/flask/app.py", line 2447, in wsgi_app
    response = self.full_dispatch_request()
  File "/home/mayank1729/microblog/venv/lib/python3.8/site-packages/flask/app.py", line 1952, in full_dispatch_request
    rv = self.handle_user_exception(e)
  File "/home/mayank1729/microblog/venv/lib/python3.8/site-packages/flask/app.py", line 1821, in handle_user_exception
    reraise(exc_type, exc_value, tb)
  File "/home/mayank1729/microblog/venv/lib/python3.8/site-packages/flask/_compat.py", line 39, in reraise
    raise value
  File "/home/mayank1729/microblog/venv/lib/python3.8/site-packages/flask/app.py", line 1950, in full_dispatch_request
    rv = self.dispatch_request()
  File "/home/mayank1729/microblog/venv/lib/python3.8/site-packages/flask/app.py", line 1936, in dispatch_request
    return self.view_functions[rule.endpoint](**req.view_args)
  File "/home/mayank1729/microblog/app/routes.py", line 160, in reset_password_request
    send_password_reset_email(user)
  File "/home/mayank1729/microblog/app/email.py", line 17, in send_password_reset_email
    send_mail('[Microblog] Reset Your Password',sender = app.config['ADMINS'][0],recipients=[user.email],text_body = render_template('email/reset_password.txt',user=user, token=token),html_body=render_template('email/reset_password.html',user=user, token=token))
NameError: name 'app' is not defined
2020-11-05 21:51:55,128 INFO: Microblog startup [in /home/mayank1729/microblog/app/__init__.py:43]
